<testsuite name="Mocha Tests" tests="1" failures="0" errors="1" skipped="0" timestamp="Sun, 11 Aug 2019 23:57:33 GMT" time="0.16">
<testcase classname="products Products class addNodeAsync" name="should throw on error frame." time="0.023"><failure>expected [Function] to throw an error
AssertionError: expected [Function] to throw an error
    at Context.&#x3C;anonymous&#x3E; (C:\Users\mschroeder\Source\Repos\velux-api\test\products-test.ts:154:86)
    at Generator.next (&#x3C;anonymous&#x3E;)
    at fulfilled (C:\Users\mschroeder\Source\Repos\velux-api\test\products-test.ts:4:58)</failure></testcase>
</testsuite>
